<?xml version="1.0" encoding="UTF-8"?>
<!-- Generated by org.testng.reporters.JUnitXMLReporter -->
<testsuite hostname="noi-harshit-w81" ignored="0" name="DummyAPISanityTest" tests="10" failures="4" timestamp="12 Jul 2017 05:08:32 GMT" time="0.111" errors="0">
  <testcase name="TempTest1" time="0.006" classname="tests.TestClass"/>
  <testcase name="TempTest10" time="0.001" classname="tests.TestClass2"/>
  <testcase name="TempTest4" time="0.01" classname="tests.TestClass">
    <failure type="java.lang.AssertionError" message="The following asserts failed:
	expected [4] but found [5]">
      <![CDATA[java.lang.AssertionError: The following asserts failed:
	expected [4] but found [5]
	at assertions.MTAssertion.assertAll(MTAssertion.java:11)
	at tests.TestClass.TempTest4(TestClass.java:69)
	at java.util.concurrent.ThreadPoolExecutor.runWorker(ThreadPoolExecutor.java:1142)
	at java.util.concurrent.ThreadPoolExecutor$Worker.run(ThreadPoolExecutor.java:617)
	at java.lang.Thread.run(Thread.java:745)
... Removed 11 stack frames]]>
    </failure>
  </testcase> <!-- TempTest4 -->
  <testcase name="TempTest6" time="0.0" classname="tests.TestClass2"/>
  <testcase name="TempTest3" time="0.041" classname="tests.TestClass">
    <failure type="java.lang.AssertionError" message="The following asserts failed:
	expected [3] but found [4]">
      <![CDATA[java.lang.AssertionError: The following asserts failed:
	expected [3] but found [4]
	at assertions.MTAssertion.assertAll(MTAssertion.java:11)
	at tests.TestClass.TempTest3(TestClass.java:54)
	at java.util.concurrent.ThreadPoolExecutor.runWorker(ThreadPoolExecutor.java:1142)
	at java.util.concurrent.ThreadPoolExecutor$Worker.run(ThreadPoolExecutor.java:617)
	at java.lang.Thread.run(Thread.java:745)
... Removed 11 stack frames]]>
    </failure>
  </testcase> <!-- TempTest3 -->
  <testcase name="TempTest8" time="0.001" classname="tests.TestClass2">
    <failure type="java.lang.AssertionError" message="The following asserts failed:
	expected [8] but found [9]">
      <![CDATA[java.lang.AssertionError: The following asserts failed:
	expected [8] but found [9]
	at assertions.MTAssertion.assertAll(MTAssertion.java:11)
	at tests.TestClass2.TempTest8(TestClass2.java:52)
	at java.util.concurrent.ThreadPoolExecutor.runWorker(ThreadPoolExecutor.java:1142)
	at java.util.concurrent.ThreadPoolExecutor$Worker.run(ThreadPoolExecutor.java:617)
	at java.lang.Thread.run(Thread.java:745)
... Removed 11 stack frames]]>
    </failure>
  </testcase> <!-- TempTest8 -->
  <testcase name="TempTest9" time="0.0" classname="tests.TestClass2">
    <failure type="java.lang.AssertionError" message="The following asserts failed:
	expected [9] but found [10]">
      <![CDATA[java.lang.AssertionError: The following asserts failed:
	expected [9] but found [10]
	at assertions.MTAssertion.assertAll(MTAssertion.java:11)
	at tests.TestClass2.TempTest9(TestClass2.java:67)
	at java.util.concurrent.ThreadPoolExecutor.runWorker(ThreadPoolExecutor.java:1142)
	at java.util.concurrent.ThreadPoolExecutor$Worker.run(ThreadPoolExecutor.java:617)
	at java.lang.Thread.run(Thread.java:745)
... Removed 11 stack frames]]>
    </failure>
  </testcase> <!-- TempTest9 -->
  <testcase name="TempTest7" time="0.006" classname="tests.TestClass2"/>
  <testcase name="TempTest2" time="0.0" classname="tests.TestClass"/>
  <testcase name="TempTest5" time="0.0" classname="tests.TestClass"/>
</testsuite> <!-- DummyAPISanityTest -->
