<?xml version="1.0" encoding="UTF-8"?>
<!-- Generated by org.testng.reporters.JUnitReportReporter -->
<testsuite name="tests.TestClass" tests="5" time="0.115" ignored="0" failures="2" timestamp="12 Jul 2017 05:09:02 GMT" skipped="0" hostname="noi-harshit-w81" errors="0">
  <testcase name="TempTest5" time="0.025" classname="tests.TestClass"/>
  <testcase name="TempTest3" time="0.033" classname="tests.TestClass">
    <failure type="java.lang.AssertionError" message="The following asserts failed:
	expected [3] but found [4]">
      <![CDATA[java.lang.AssertionError: The following asserts failed:
	expected [3] but found [4]
	at org.testng.asserts.SoftAssert.assertAll(SoftAssert.java:43)
	at assertions.MTAssertion.assertAll(MTAssertion.java:11)
	at tests.TestClass.TempTest3(TestClass.java:54)
	at sun.reflect.NativeMethodAccessorImpl.invoke0(Native Method)
	at sun.reflect.NativeMethodAccessorImpl.invoke(NativeMethodAccessorImpl.java:62)
	at sun.reflect.DelegatingMethodAccessorImpl.invoke(DelegatingMethodAccessorImpl.java:43)
	at java.lang.reflect.Method.invoke(Method.java:498)
	at org.testng.internal.MethodInvocationHelper.invokeMethod(MethodInvocationHelper.java:104)
	at org.testng.internal.Invoker.invokeMethod(Invoker.java:645)
	at org.testng.internal.Invoker.invokeTestMethod(Invoker.java:851)
	at org.testng.internal.Invoker.invokeTestMethods(Invoker.java:1177)
	at org.testng.internal.TestMethodWorker.invokeTestMethods(TestMethodWorker.java:129)
	at org.testng.internal.TestMethodWorker.run(TestMethodWorker.java:112)
	at java.util.concurrent.ThreadPoolExecutor.runWorker(ThreadPoolExecutor.java:1142)
	at java.util.concurrent.ThreadPoolExecutor$Worker.run(ThreadPoolExecutor.java:617)
	at java.lang.Thread.run(Thread.java:745)
]]>
    </failure>
  </testcase> <!-- TempTest3 -->
  <testcase name="TempTest1" time="0.011" classname="tests.TestClass"/>
  <testcase name="TempTest2" time="0.010" classname="tests.TestClass"/>
  <testcase name="TempTest4" time="0.036" classname="tests.TestClass">
    <failure type="java.lang.AssertionError" message="The following asserts failed:
	expected [4] but found [5]">
      <![CDATA[java.lang.AssertionError: The following asserts failed:
	expected [4] but found [5]
	at org.testng.asserts.SoftAssert.assertAll(SoftAssert.java:43)
	at assertions.MTAssertion.assertAll(MTAssertion.java:11)
	at tests.TestClass.TempTest4(TestClass.java:69)
	at sun.reflect.NativeMethodAccessorImpl.invoke0(Native Method)
	at sun.reflect.NativeMethodAccessorImpl.invoke(NativeMethodAccessorImpl.java:62)
	at sun.reflect.DelegatingMethodAccessorImpl.invoke(DelegatingMethodAccessorImpl.java:43)
	at java.lang.reflect.Method.invoke(Method.java:498)
	at org.testng.internal.MethodInvocationHelper.invokeMethod(MethodInvocationHelper.java:104)
	at org.testng.internal.Invoker.invokeMethod(Invoker.java:645)
	at org.testng.internal.Invoker.invokeTestMethod(Invoker.java:851)
	at org.testng.internal.Invoker.invokeTestMethods(Invoker.java:1177)
	at org.testng.internal.TestMethodWorker.invokeTestMethods(TestMethodWorker.java:129)
	at org.testng.internal.TestMethodWorker.run(TestMethodWorker.java:112)
	at java.util.concurrent.ThreadPoolExecutor.runWorker(ThreadPoolExecutor.java:1142)
	at java.util.concurrent.ThreadPoolExecutor$Worker.run(ThreadPoolExecutor.java:617)
	at java.lang.Thread.run(Thread.java:745)
]]>
    </failure>
  </testcase> <!-- TempTest4 -->
</testsuite> <!-- tests.TestClass -->
