<?xml version="1.0" encoding="UTF-8"?>
<!-- Generated by org.testng.reporters.JUnitReportReporter -->
<testsuite name="tests.TestClass1" tests="5" time="0.307" ignored="0" failures="2" timestamp="12 Jul 2017 10:21:09 GMT" skipped="0" hostname="noi-harshit-w81" errors="0">
  <testcase name="TempTest1" time="0.028" classname="tests.TestClass1"/>
  <testcase name="TempTest4" time="0.083" classname="tests.TestClass1">
    <failure type="java.lang.AssertionError" message="The following asserts failed:
	expected [4] but found [5]">
      <![CDATA[java.lang.AssertionError: The following asserts failed:
	expected [4] but found [5]
	at org.testng.asserts.SoftAssert.assertAll(SoftAssert.java:43)
	at assertions.MyAssertion.assertAll(MyAssertion.java:11)
	at tests.TestClass1.TempTest4(TestClass1.java:41)
	at sun.reflect.NativeMethodAccessorImpl.invoke0(Native Method)
	at sun.reflect.NativeMethodAccessorImpl.invoke(NativeMethodAccessorImpl.java:62)
	at sun.reflect.DelegatingMethodAccessorImpl.invoke(DelegatingMethodAccessorImpl.java:43)
	at java.lang.reflect.Method.invoke(Method.java:498)
	at org.testng.internal.MethodInvocationHelper.invokeMethod(MethodInvocationHelper.java:104)
	at org.testng.internal.Invoker.invokeMethod(Invoker.java:645)
	at org.testng.internal.Invoker.invokeTestMethod(Invoker.java:851)
	at org.testng.internal.Invoker.invokeTestMethods(Invoker.java:1177)
	at org.testng.internal.TestMethodWorker.invokeTestMethods(TestMethodWorker.java:129)
	at org.testng.internal.TestMethodWorker.run(TestMethodWorker.java:112)
	at java.util.concurrent.ThreadPoolExecutor.runWorker(ThreadPoolExecutor.java:1142)
	at java.util.concurrent.ThreadPoolExecutor$Worker.run(ThreadPoolExecutor.java:617)
	at java.lang.Thread.run(Thread.java:745)
]]>
    </failure>
  </testcase> <!-- TempTest4 -->
  <testcase name="TempTest5" time="0.086" classname="tests.TestClass1"/>
  <testcase name="TempTest3" time="0.031" classname="tests.TestClass1">
    <failure type="java.lang.AssertionError" message="The following asserts failed:
	expected [3] but found [4]">
      <![CDATA[java.lang.AssertionError: The following asserts failed:
	expected [3] but found [4]
	at org.testng.asserts.SoftAssert.assertAll(SoftAssert.java:43)
	at assertions.MyAssertion.assertAll(MyAssertion.java:11)
	at tests.TestClass1.TempTest3(TestClass1.java:33)
	at sun.reflect.NativeMethodAccessorImpl.invoke0(Native Method)
	at sun.reflect.NativeMethodAccessorImpl.invoke(NativeMethodAccessorImpl.java:62)
	at sun.reflect.DelegatingMethodAccessorImpl.invoke(DelegatingMethodAccessorImpl.java:43)
	at java.lang.reflect.Method.invoke(Method.java:498)
	at org.testng.internal.MethodInvocationHelper.invokeMethod(MethodInvocationHelper.java:104)
	at org.testng.internal.Invoker.invokeMethod(Invoker.java:645)
	at org.testng.internal.Invoker.invokeTestMethod(Invoker.java:851)
	at org.testng.internal.Invoker.invokeTestMethods(Invoker.java:1177)
	at org.testng.internal.TestMethodWorker.invokeTestMethods(TestMethodWorker.java:129)
	at org.testng.internal.TestMethodWorker.run(TestMethodWorker.java:112)
	at java.util.concurrent.ThreadPoolExecutor.runWorker(ThreadPoolExecutor.java:1142)
	at java.util.concurrent.ThreadPoolExecutor$Worker.run(ThreadPoolExecutor.java:617)
	at java.lang.Thread.run(Thread.java:745)
]]>
    </failure>
  </testcase> <!-- TempTest3 -->
  <testcase name="TempTest2" time="0.079" classname="tests.TestClass1"/>
</testsuite> <!-- tests.TestClass1 -->
