<?xml version="1.0" encoding="UTF-8"?>
<!-- Generated by org.testng.reporters.JUnitReportReporter -->
<testsuite name="tests.TestClass2" tests="5" time="0.002" ignored="0" failures="2" timestamp="12 Jul 2017 10:21:09 GMT" skipped="0" hostname="noi-harshit-w81" errors="0">
  <testcase name="TempTest6" time="0.000" classname="tests.TestClass2"/>
  <testcase name="TempTest7" time="0.000" classname="tests.TestClass2"/>
  <testcase name="TempTest10" time="0.001" classname="tests.TestClass2"/>
  <testcase name="TempTest8" time="0.000" classname="tests.TestClass2">
    <failure type="java.lang.AssertionError" message="The following asserts failed:
	expected [8] but found [9]">
      <![CDATA[java.lang.AssertionError: The following asserts failed:
	expected [8] but found [9]
	at org.testng.asserts.SoftAssert.assertAll(SoftAssert.java:43)
	at assertions.MyAssertion.assertAll(MyAssertion.java:11)
	at tests.TestClass2.TempTest8(TestClass2.java:34)
	at sun.reflect.NativeMethodAccessorImpl.invoke0(Native Method)
	at sun.reflect.NativeMethodAccessorImpl.invoke(NativeMethodAccessorImpl.java:62)
	at sun.reflect.DelegatingMethodAccessorImpl.invoke(DelegatingMethodAccessorImpl.java:43)
	at java.lang.reflect.Method.invoke(Method.java:498)
	at org.testng.internal.MethodInvocationHelper.invokeMethod(MethodInvocationHelper.java:104)
	at org.testng.internal.Invoker.invokeMethod(Invoker.java:645)
	at org.testng.internal.Invoker.invokeTestMethod(Invoker.java:851)
	at org.testng.internal.Invoker.invokeTestMethods(Invoker.java:1177)
	at org.testng.internal.TestMethodWorker.invokeTestMethods(TestMethodWorker.java:129)
	at org.testng.internal.TestMethodWorker.run(TestMethodWorker.java:112)
	at java.util.concurrent.ThreadPoolExecutor.runWorker(ThreadPoolExecutor.java:1142)
	at java.util.concurrent.ThreadPoolExecutor$Worker.run(ThreadPoolExecutor.java:617)
	at java.lang.Thread.run(Thread.java:745)
]]>
    </failure>
  </testcase> <!-- TempTest8 -->
  <testcase name="TempTest9" time="0.001" classname="tests.TestClass2">
    <failure type="java.lang.AssertionError" message="The following asserts failed:
	expected [9] but found [10]">
      <![CDATA[java.lang.AssertionError: The following asserts failed:
	expected [9] but found [10]
	at org.testng.asserts.SoftAssert.assertAll(SoftAssert.java:43)
	at assertions.MyAssertion.assertAll(MyAssertion.java:11)
	at tests.TestClass2.TempTest9(TestClass2.java:42)
	at sun.reflect.NativeMethodAccessorImpl.invoke0(Native Method)
	at sun.reflect.NativeMethodAccessorImpl.invoke(NativeMethodAccessorImpl.java:62)
	at sun.reflect.DelegatingMethodAccessorImpl.invoke(DelegatingMethodAccessorImpl.java:43)
	at java.lang.reflect.Method.invoke(Method.java:498)
	at org.testng.internal.MethodInvocationHelper.invokeMethod(MethodInvocationHelper.java:104)
	at org.testng.internal.Invoker.invokeMethod(Invoker.java:645)
	at org.testng.internal.Invoker.invokeTestMethod(Invoker.java:851)
	at org.testng.internal.Invoker.invokeTestMethods(Invoker.java:1177)
	at org.testng.internal.TestMethodWorker.invokeTestMethods(TestMethodWorker.java:129)
	at org.testng.internal.TestMethodWorker.run(TestMethodWorker.java:112)
	at java.util.concurrent.ThreadPoolExecutor.runWorker(ThreadPoolExecutor.java:1142)
	at java.util.concurrent.ThreadPoolExecutor$Worker.run(ThreadPoolExecutor.java:617)
	at java.lang.Thread.run(Thread.java:745)
]]>
    </failure>
  </testcase> <!-- TempTest9 -->
</testsuite> <!-- tests.TestClass2 -->
